<robot name="rover">
    <link name="base_link">
        <inertial>
            <mass value="5.0"/>
            <origin xyz="0 0 0"/>
        </inertial>
        <visual>
            <geometry>
                <box size="0.5 0.3 0.2"/>
            </geometry>
        </visual>
        <collision>
            <geometry>
                <box size="0.5 0.3 0.2"/>
            </geometry>
        </collision>
    </link>

    <joint name="wheel_left_joint" type="continuous">
        <parent link="base_link"/>
        <child link="wheel_left"/>
        <origin xyz="-0.2 0 0"/>
    </joint>

    <joint name="wheel_right_joint" type="continuous">
        <parent link="base_link"/>
        <child link="wheel_right"/>
        <origin xyz="0.2 0 0"/>
    </joint>
</robot>
